<?xml version="1.0" ?>
<robot name="ergojr-pusher" xmlns:xacro="http://www.ros.org/wiki/xacro">
  <material name="white">
    <color rgba="1 1 1 1"/>
  </material>
  <material name="black">
    <color rgba="0 0 0 1"/>
  </material>
  <material name="red">
    <color rgba="1 0 0 1"/>
  </material>
  <link name="1_anchor">
    <inertial>
      <mass value="1"/>
      <inertia ixx="1" iyy="1" izz="1"/>
    </inertial>
  </link>
  <joint name="1_anchor_to_base" type="fixed">
    <parent link="1_anchor"/>
    <child link="1_base"/>
    <origin rpy="0 0 0" xyz="0 0 0"/>
  </joint>
  <link name="1_base">
    <visual>
      <origin xyz="0 0 .005"/>
      <geometry>
        <box size=".02 .02 .01"/>
      </geometry>
      <material name="white"/>
    </visual>
    <collision>
      <origin xyz="0 0 .005"/>
      <geometry>
        <box size=".02 .02 .01"/>
      </geometry>
    </collision>
  </link>
  <joint name="1_motor1_joint" type="revolute">
    <parent link="1_base"/>
    <child link="1_motor1_link"/>
    <origin xyz="0 0 .01"/>
    <limit effort="100.0" lower="-1.570796326795" upper="1.570796326795" velocity="0.5"/>
    <axis xyz="0 0 1"/>
  </joint>
  <link name="1_motor1_link">
    <visual>
      <origin rpy="0 0 0" xyz="0 0.009 0.0135"/>
      <geometry>
        <box size=".024 .036 .027"/>
      </geometry>
      <material name="black"/>
    </visual>
    <collision>
      <origin rpy="0 0 0" xyz="0 0.009 0.0135"/>
      <geometry>
        <box size=".024 .036 .027"/>
      </geometry>
    </collision>
    <inertial>
      <!--ACTUAL MASS-->
      <!--<mass value=".017"/>-->
      <!--NORMAL WORKING MASS-->
      <mass value=".1"/>
      <inertia ixx="1e-3" iyy="1e-3" izz="1e-3"/>
    </inertial>
  </link>
  <joint name="1_motor1bridge2" type="fixed">
    <parent link="1_motor1_link"/>
    <child link="1_motor1bridge2_link"/>
    <origin xyz="0 .027 0"/>
  </joint>
  <link name="1_motor1bridge2_link">
    <visual>
      <origin xyz="0 .0145 -.001"/>
      <geometry>
        <box size=".02 .045 .002"/>
      </geometry>
      <material name="white"/>
    </visual>
    <collision>
      <origin xyz="0 .0145 -.001"/>
      <geometry>
        <box size=".02 .045 .002"/>
      </geometry>
    </collision>
    <visual>
      <origin xyz="0 .0145 .028"/>
      <geometry>
        <box size=".02 .045 .002"/>
      </geometry>
      <material name="white"/>
    </visual>
    <collision>
      <origin xyz="0 .0145 .028"/>
      <geometry>
        <box size=".02 .045 .002"/>
      </geometry>
    </collision>
  </link>
  <joint name="1_motor2_joint" type="revolute">
    <parent link="1_motor1bridge2_link"/>
    <child link="1_motor2_link"/>
    <origin xyz="0 .027 0"/>
    <limit effort="100.0" lower="-1.570796326795" upper="1.570796326795" velocity="0.5"/>
    <axis xyz="0 0 1"/>
  </joint>
  <link name="1_motor2_link">
    <visual>
      <origin rpy="0 0 0" xyz="0 0.009 0.0135"/>
      <geometry>
        <box size=".024 .036 .027"/>
      </geometry>
      <material name="black"/>
    </visual>
    <collision>
      <origin rpy="0 0 0" xyz="0 0.009 0.0135"/>
      <geometry>
        <box size=".024 .036 .027"/>
      </geometry>
    </collision>
    <inertial>
      <!--ACTUAL MASS-->
      <!--<mass value=".017"/>-->
      <!--NORMAL WORKING MASS-->
      <mass value=".1"/>
      <inertia ixx="1e-3" iyy="1e-3" izz="1e-3"/>
    </inertial>
  </link>
  <joint name="1_motor2bridge3" type="fixed">
    <parent link="1_motor2_link"/>
    <child link="1_motor2bridge3_link"/>
    <origin xyz="0 .027 0"/>
  </joint>
  <link name="1_motor2bridge3_link">
    <visual>
      <origin xyz="0 .0145 -.001"/>
      <geometry>
        <box size=".02 .045 .002"/>
      </geometry>
      <material name="white"/>
    </visual>
    <collision>
      <origin xyz="0 .0145 -.001"/>
      <geometry>
        <box size=".02 .045 .002"/>
      </geometry>
    </collision>
    <visual>
      <origin xyz="0 .0145 .028"/>
      <geometry>
        <box size=".02 .045 .002"/>
      </geometry>
      <material name="white"/>
    </visual>
    <collision>
      <origin xyz="0 .0145 .028"/>
      <geometry>
        <box size=".02 .045 .002"/>
      </geometry>
    </collision>
  </link>
  <joint name="1_motor3_joint" type="revolute">
    <parent link="1_motor2bridge3_link"/>
    <child link="1_motor3_link"/>
    <origin xyz="0 .027 0"/>
    <limit effort="100.0" lower="-1.570796326795" upper="1.570796326795" velocity="0.5"/>
    <axis xyz="0 0 1"/>
  </joint>
  <link name="1_motor3_link">
    <visual>
      <origin rpy="0 0 0" xyz="0 0.009 0.0135"/>
      <geometry>
        <box size=".024 .036 .027"/>
      </geometry>
      <material name="black"/>
    </visual>
    <collision>
      <origin rpy="0 0 0" xyz="0 0.009 0.0135"/>
      <geometry>
        <box size=".024 .036 .027"/>
      </geometry>
    </collision>
    <inertial>
      <!--ACTUAL MASS-->
      <!--<mass value=".017"/>-->
      <!--NORMAL WORKING MASS-->
      <mass value=".1"/>
      <inertia ixx="1e-3" iyy="1e-3" izz="1e-3"/>
    </inertial>
  </link>
  <!--    TODO: put end effector code here-->
</robot>
