<?xml version="1.0" ?>
<robot name="puck" xmlns:xacro="http://www.ros.org/wiki/xacro">
    <xacro:include filename="ergojr-pusher-macros.xacro.xml"/>
    <xacro:property name="mass" value=".1"/>

    <link name="2_anchor">
        <inertial>
            <mass value="1"/>
            <inertia ixx="1" iyy="1" izz="1"/>
        </inertial>
    </link>


    <joint name="2_puck_to_world" type="prismatic">
        <parent link="2_anchor"/>
        <child link="2_puck_y"/>
        <axis xyz="0 1 0"/>
        <limit effort="0.0" lower="-1" upper="1" velocity="1000.0"/>
    </joint>

    <link name="2_puck_y">
        <inertial>
            <mass value="${mass}"/>
            <xacro:cylinder_inertia m="${mass}" r=".02" h=".03"/>
            <origin rpy="0 0 0" xyz="0 0 0"/>
        </inertial>
    </link>

    <joint name="2_puck_y_to_z" type="prismatic">
        <parent link="2_puck_y"/>
        <child link="2_puck"/>
        <axis xyz="1 0 0"/>
        <limit effort="0.0" lower="-1" upper="1" velocity="1000.0"/>
    </joint>

    <!--    <link name="2_puck_z">-->
    <!--        <inertial>-->
    <!--            <mass value="0.01"/>-->
    <!--            <inertia ixx="0.2125" ixy="-0.005" ixz="0.0225" iyy="0.205" iyz="0.045" izz="0.0125"/>-->
    <!--            <origin rpy="0 0 0" xyz="0 0 0"/>-->
    <!--        </inertial>-->
    <!--    </link>-->

    <!--    <joint name="2_puck_z_to_puck" type="continuous">-->
    <!--        <parent link="2_puck_z"/>-->
    <!--        <child link="2_puck"/>-->
    <!--        <axis xyz="0 0 1"/>-->
    <!--    </joint>-->

    <link name="2_puck">
        <xacro:cylinder2 length=".03" radius=".02" posz=".015" color="red"/>
        <inertial>
            <mass value="${mass}"/>
            <xacro:cylinder_inertia m="${mass}" r=".02" h=".03"/>
            <origin rpy="0 0 0" xyz="0 0 0"/>
        </inertial>
    </link>


</robot>
