<?xml version="1.0" ?>
<robot name="ergojr-sword" xmlns:xacro="http://www.ros.org/wiki/xacro">
    <material name="white">
        <color rgba="1 1 1 1"/>
    </material>
    <material name="black">
        <color rgba="0 0 0 1"/>
    </material>
    <material name="red">
        <color rgba="1 0 0 1"/>
    </material>
    <material name="white">
        <color rgba="1 1 1 1"/>
    </material>
    <material name="black">
        <color rgba="0 0 0 1"/>
    </material>
    <material name="red">
        <color rgba="1 0 0 1"/>
    </material>
    <material name="white">
        <color rgba="1 1 1 1"/>
    </material>
    <material name="black">
        <color rgba="0 0 0 1"/>
    </material>
    <material name="red">
        <color rgba="1 0 0 1"/>
    </material>
    <material name="white">
        <color rgba="1 1 1 1"/>
    </material>
    <material name="black">
        <color rgba="0 0 0 1"/>
    </material>
    <material name="red">
        <color rgba="1 0 0 1"/>
    </material>
    <link name="1_anchor"/>
    <joint name="1_anchor_to_base" type="fixed">
        <parent link="1_anchor"/>
        <child link="1_base"/>
        <origin rpy="0 0 0" xyz="0 0 0"/>
    </joint>
    <link name="1_base">
        <visual>
            <origin rpy="0 0 0" xyz="0 0 0.0025"/>
            <geometry>
                <cylinder length="0.005" radius="0.075"/>
            </geometry>
            <material name="white"/>
        </visual>
        <collision>
            <origin rpy="0 0 0" xyz="0 0 0.0025"/>
            <geometry>
                <cylinder length="0.005" radius="0.075"/>
            </geometry>
        </collision>
        <inertial>
            <mass value=".038"/>
            <inertia ixx="1e-3" iyy="1e-3" izz="1e-3"/>
            <!--<inertia ixx="0.4" ixy="0.0" ixz="0.0" iyy="0.4" iyz="0.0" izz="0.2"/>-->
        </inertial>
    </link>
    <joint name="1_base_to_static" type="fixed">
        <parent link="1_base"/>
        <child link="1_static_first_link"/>
        <origin xyz="0 .038 0.005"/>
    </joint>
    <!--<joint name="base_to_measure" type="fixed">-->
    <!--<parent link="base"/>-->
    <!--<child link="ruler"/>-->
    <!--</joint>-->
    <!--<link name="ruler">-->
    <!--<xacro:box2 nocoll="1" sizex=".02" sizey=".02" sizez=".17" color="red" posz=".085"/>-->
    <!--</link>-->
    <link name="1_static_first_link">
        <visual>
            <origin rpy="0 0 0" xyz="0 0 0.0015"/>
            <geometry>
                <cylinder length="0.003" radius="0.0275"/>
            </geometry>
            <material name="white"/>
        </visual>
        <collision>
            <origin rpy="0 0 0" xyz="0 0 0.0015"/>
            <geometry>
                <cylinder length="0.003" radius="0.0275"/>
            </geometry>
        </collision>
        <inertial>
            <mass value="0.011"/>
            <inertia ixx="1e-5" iyy="1e-5" izz="1e-5"/>
            <!--<inertia ixx="0.4" ixy="0.0" ixz="0.0" iyy="0.4" iyz="0.0" izz="0.2"/>-->
        </inertial>
    </link>
    <joint name="1_motor1_to_static" type="fixed">
        <parent link="1_static_first_link"/>
        <child link="1_motor1link"/>
        <origin xyz="0 -.010 .003"/>
    </joint>
    <link name="1_motor1link">
        <visual>
            <origin rpy="0 0 0" xyz="0 0 0.0135"/>
            <geometry>
                <box size=".024 .035 .027"/>
            </geometry>
            <material name="black"/>
        </visual>
        <collision>
            <origin rpy="0 0 0" xyz="0 0 0.0135"/>
            <geometry>
                <box size=".024 .035 .027"/>
            </geometry>
        </collision>
        <inertial>
            <!--ACTUAL MASS-->
            <!--<mass value=".017"/>-->
            <!--NORMAL WORKING MASS-->
            <mass value=".1"/>
            <!--<inertia ixx="0.4" ixy="0.0" ixz="0.0" iyy="0.4" iyz="0.0" izz="0.2"/>-->
            <inertia ixx="1e-3" iyy="1e-3" izz="1e-3"/>
        </inertial>
    </link>
    <joint name="1_motor1joint" type="revolute">
        <parent link="1_motor1link"/>
        <child link="1_link1_bottom"/>
        <origin rpy="0 0 0" xyz="0 .0095 .027"/>
        <limit effort="100.0" lower="-1.570796326795" upper="1.570796326795" velocity="0.5"/>
        <axis xyz="0 0 1"/>
    </joint>
    <link name="1_link1_bottom">
        <visual>
            <origin rpy="0 0 0" xyz="0 0 0.001"/>
            <geometry>
                <box size="0.034 0.02 0.002"/>
            </geometry>
            <material name="white"/>
        </visual>
        <collision>
            <origin rpy="0 0 0" xyz="0 0 0.001"/>
            <geometry>
                <box size="0.034 0.02 0.002"/>
            </geometry>
        </collision>
        <visual>
            <origin rpy="0 0 0" xyz="-0.016 0 0.01725"/>
            <geometry>
                <box size="0.002 0.02 0.0345"/>
            </geometry>
            <material name="white"/>
        </visual>
        <collision>
            <origin rpy="0 0 0" xyz="-0.016 0 0.01725"/>
            <geometry>
                <box size="0.002 0.02 0.0345"/>
            </geometry>
        </collision>
        <visual>
            <origin rpy="0 0 0" xyz="0.0145 0 0.01725"/>
            <geometry>
                <box size="0.005 0.02 0.0345"/>
            </geometry>
            <material name="white"/>
        </visual>
        <collision>
            <origin rpy="0 0 0" xyz="0.0145 0 0.01725"/>
            <geometry>
                <box size="0.005 0.02 0.0345"/>
            </geometry>
        </collision>
        <inertial>
            <mass value=".005"/>
            <inertia ixx="1e-5" iyy="1e-5" izz="1e-5"/>
            <!--<inertia ixx="0.4" ixy="0.0" ixz="0.0" iyy="0.4" iyz="0.0" izz="0.2"/>-->
        </inertial>
    </link>
    <joint name="1_motor2joint" type="revolute">
        <parent link="1_link1_bottom"/>
        <child link="1_motor2link"/>
        <origin xyz="0 0 .024"/>
        <limit effort="100.0" lower="-1.570796326795" upper="1.570796326795" velocity="0.5"/>
        <axis xyz="1 0 0"/>
    </joint>
    <link name="1_motor2link">
        <visual>
            <origin rpy="1.570796326795 0 1.570796326795" xyz="-0.0015 0 0.0095"/>
            <geometry>
                <box size=".024 .035 .027"/>
            </geometry>
            <material name="black"/>
        </visual>
        <collision>
            <origin rpy="1.570796326795 0 1.570796326795" xyz="-0.0015 0 0.0095"/>
            <geometry>
                <box size=".024 .035 .027"/>
            </geometry>
        </collision>
        <inertial>
            <!--ACTUAL MASS-->
            <!--<mass value=".017"/>-->
            <!--NORMAL WORKING MASS-->
            <mass value=".1"/>
            <!--<inertia ixx="0.4" ixy="0.0" ixz="0.0" iyy="0.4" iyz="0.0" izz="0.2"/>-->
            <inertia ixx="1e-3" iyy="1e-3" izz="1e-3"/>
        </inertial>
    </link>
    <joint name="1_motor2link_to_motor2bridge3" type="fixed">
        <parent link="1_motor2link"/>
        <child link="1_motor2bridge3"/>
        <origin xyz="0 0 .019"/>
    </joint>
    <link name="1_motor2bridge3">
        <visual>
            <origin rpy="0 0 0" xyz="-0.016 0 0.0225"/>
            <geometry>
                <box size="0.002 0.02 0.045"/>
            </geometry>
            <material name="white"/>
        </visual>
        <collision>
            <origin rpy="0 0 0" xyz="-0.016 0 0.0225"/>
            <geometry>
                <box size="0.002 0.02 0.045"/>
            </geometry>
        </collision>
        <visual>
            <origin rpy="0 0 0" xyz="0.0145 0 0.0225"/>
            <geometry>
                <box size="0.005 0.02 0.045"/>
            </geometry>
            <material name="white"/>
        </visual>
        <collision>
            <origin rpy="0 0 0" xyz="0.0145 0 0.0225"/>
            <geometry>
                <box size="0.005 0.02 0.045"/>
            </geometry>
        </collision>
        <inertial>
            <mass value=".0045"/>
            <inertia ixx="1e-5" iyy="1e-5" izz="1e-5"/>
            <!--<inertia ixx="0.4" ixy="0.0" ixz="0.0" iyy="0.4" iyz="0.0" izz="0.2"/>-->
        </inertial>
    </link>
    <joint name="1_motor3joint" type="revolute">
        <parent link="1_motor2bridge3"/>
        <child link="1_motor3link"/>
        <origin xyz="0 0 .035"/>
        <limit effort="100.0" lower="-1.570796326795" upper="1.570796326795" velocity="0.5"/>
        <axis xyz="1 0 0"/>
    </joint>
    <link name="1_motor3link">
        <visual>
            <origin rpy="1.570796326795 0 1.570796326795" xyz="-0.0015 0 0.0095"/>
            <geometry>
                <box size=".024 .035 .027"/>
            </geometry>
            <material name="black"/>
        </visual>
        <collision>
            <origin rpy="1.570796326795 0 1.570796326795" xyz="-0.0015 0 0.0095"/>
            <geometry>
                <box size=".024 .035 .027"/>
            </geometry>
        </collision>
        <inertial>
            <!--ACTUAL MASS-->
            <!--<mass value=".017"/>-->
            <!--NORMAL WORKING MASS-->
            <mass value=".1"/>
            <!--<inertia ixx="0.4" ixy="0.0" ixz="0.0" iyy="0.4" iyz="0.0" izz="0.2"/>-->
            <inertia ixx="1e-3" iyy="1e-3" izz="1e-3"/>
        </inertial>
    </link>
    <joint name="1_motor3link_to_motor2bridge3" type="fixed">
        <parent link="1_motor3link"/>
        <child link="1_motor3bridge4"/>
        <origin xyz="0 0 .026"/>
    </joint>
    <link name="1_motor3bridge4">
        <visual>
            <origin rpy="0 0 0" xyz="-0.0015 0 0.002"/>
            <geometry>
                <box size="0.027 0.02 0.002"/>
            </geometry>
            <material name="white"/>
        </visual>
        <collision>
            <origin rpy="0 0 0" xyz="-0.0015 0 0.002"/>
            <geometry>
                <box size="0.027 0.02 0.002"/>
            </geometry>
        </collision>
        <inertial>
            <mass value=".001"/>
            <inertia ixx="1e-5" iyy="1e-5" izz="1e-5"/>
            <!--<inertia ixx="0.4" ixy="0.0" ixz="0.0" iyy="0.4" iyz="0.0" izz="0.2"/>-->
        </inertial>
    </link>
    <joint name="1_motor4joint" type="revolute">
        <parent link="1_motor3bridge4"/>
        <child link="1_motor4link"/>
        <origin xyz="0 0 .002"/>
        <limit effort="100.0" lower="-1.570796326795" upper="1.570796326795" velocity="0.5"/>
        <axis xyz="0 0 1"/>
    </joint>
    <link name="1_motor4link">
        <visual>
            <origin rpy="3.14159265359 0 0" xyz="0 0.0095 0.0145"/>
            <geometry>
                <box size=".024 .035 .027"/>
            </geometry>
            <material name="black"/>
        </visual>
        <collision>
            <origin rpy="3.14159265359 0 0" xyz="0 0.0095 0.0145"/>
            <geometry>
                <box size=".024 .035 .027"/>
            </geometry>
        </collision>
        <inertial>
            <!--ACTUAL MASS-->
            <!--<mass value=".017"/>-->
            <!--NORMAL WORKING MASS-->
            <mass value=".1"/>
            <!--<inertia ixx="0.4" ixy="0.0" ixz="0.0" iyy="0.4" iyz="0.0" izz="0.2"/>-->
            <inertia ixx="1e-3" iyy="1e-3" izz="1e-3"/>
        </inertial>
        <!--<xacro:box2 sizex=".5" sizey=".002" sizez=".002" color="red"/>-->
    </link>
    <joint name="1_motor4link_to_motor4bridge5" type="fixed">
        <parent link="1_motor4link"/>
        <child link="1_motor4bridge5"/>
        <origin xyz="0 .013 .015"/>
    </joint>
    <link name="1_motor4bridge5">
        <visual>
            <origin rpy="0 0 0" xyz="-0.016 0.0225 0"/>
            <geometry>
                <box size="0.002 0.045 0.02"/>
            </geometry>
            <material name="white"/>
        </visual>
        <collision>
            <origin rpy="0 0 0" xyz="-0.016 0.0225 0"/>
            <geometry>
                <box size="0.002 0.045 0.02"/>
            </geometry>
        </collision>
        <visual>
            <origin rpy="0 0 0" xyz="-0.0135 0.0025 0"/>
            <geometry>
                <box size="0.003 0.005 0.02"/>
            </geometry>
            <material name="white"/>
        </visual>
        <collision>
            <origin rpy="0 0 0" xyz="-0.0135 0.0025 0"/>
            <geometry>
                <box size="0.003 0.005 0.02"/>
            </geometry>
        </collision>
        <visual>
            <origin rpy="0 0 0" xyz="0.014 0.0225 0"/>
            <geometry>
                <box size="0.004 0.045 0.02"/>
            </geometry>
            <material name="white"/>
        </visual>
        <collision>
            <origin rpy="0 0 0" xyz="0.014 0.0225 0"/>
            <geometry>
                <box size="0.004 0.045 0.02"/>
            </geometry>
        </collision>
        <inertial>
            <mass value=".0045"/>
            <inertia ixx="1e-5" iyy="1e-5" izz="1e-5"/>
            <!--<inertia ixx="0.4" ixy="0.0" ixz="0.0" iyy="0.4" iyz="0.0" izz="0.2"/>-->
        </inertial>
    </link>
    <joint name="1_motor5joint" type="revolute">
        <parent link="1_motor4bridge5"/>
        <child link="1_motor5link"/>
        <origin xyz="0 0.035 0"/>
        <limit effort="100.0" lower="-1.570796326795" upper="1.570796326795" velocity="0.5"/>
        <axis xyz="1 0 0"/>
    </joint>
    <link name="1_motor5link">
        <visual>
            <origin rpy="3.14159265359 1.570796326795 0" xyz="-0.0015 0.0095 0"/>
            <geometry>
                <box size=".024 .035 .027"/>
            </geometry>
            <material name="black"/>
        </visual>
        <collision>
            <origin rpy="3.14159265359 1.570796326795 0" xyz="-0.0015 0.0095 0"/>
            <geometry>
                <box size=".024 .035 .027"/>
            </geometry>
        </collision>
        <inertial>
            <!--ACTUAL MASS-->
            <!--<mass value=".017"/>-->
            <!--NORMAL WORKING MASS-->
            <mass value=".1"/>
            <!--<inertia ixx="0.4" ixy="0.0" ixz="0.0" iyy="0.4" iyz="0.0" izz="0.2"/>-->
            <inertia ixx="1e-3" iyy="1e-3" izz="1e-3"/>
        </inertial>
    </link>
    <joint name="1_motor5link_to_motor5bridge6" type="fixed">
        <parent link="1_motor5link"/>
        <child link="1_motor5bridge6"/>
        <origin xyz=".0 .019 .0"/>
    </joint>
    <link name="1_motor5bridge6">
        <visual>
            <origin rpy="0 0 0" xyz="-0.016 0.0225 0"/>
            <geometry>
                <box size="0.002 0.045 0.02"/>
            </geometry>
            <material name="white"/>
        </visual>
        <collision>
            <origin rpy="0 0 0" xyz="-0.016 0.0225 0"/>
            <geometry>
                <box size="0.002 0.045 0.02"/>
            </geometry>
        </collision>
        <visual>
            <origin rpy="0 0 0" xyz="0.014 0.0225 0"/>
            <geometry>
                <box size="0.004 0.045 0.02"/>
            </geometry>
            <material name="white"/>
        </visual>
        <collision>
            <origin rpy="0 0 0" xyz="0.014 0.0225 0"/>
            <geometry>
                <box size="0.004 0.045 0.02"/>
            </geometry>
        </collision>
        <inertial>
            <mass value=".0045"/>
            <inertia ixx="1e-5" iyy="1e-5" izz="1e-5"/>
            <!--<inertia ixx="0.4" ixy="0.0" ixz="0.0" iyy="0.4" iyz="0.0" izz="0.2"/>-->
        </inertial>
    </link>
    <joint name="1_motor6joint" type="revolute">
        <parent link="1_motor5bridge6"/>
        <child link="1_motor6link"/>
        <origin xyz="0 0.035 0"/>
        <limit effort="100.0" lower="-1.570796326795" upper="1.570796326795" velocity="0.5"/>
        <axis xyz="1 0 0"/>
    </joint>
    <link name="1_motor6link">
        <!--<xacro:box2 sizex=".5" sizey=".002" sizez=".002" color="red"/>-->
        <visual>
            <origin rpy="3.14159265359 1.570796326795 0" xyz="-0.0015 0.0095 0"/>
            <geometry>
                <box size=".024 .035 .027"/>
            </geometry>
            <material name="black"/>
        </visual>
        <collision>
            <origin rpy="3.14159265359 1.570796326795 0" xyz="-0.0015 0.0095 0"/>
            <geometry>
                <box size=".024 .035 .027"/>
            </geometry>
        </collision>
        <inertial>
            <!--ACTUAL MASS-->
            <!--<mass value=".017"/>-->
            <!--NORMAL WORKING MASS-->
            <mass value=".1"/>
            <!--<inertia ixx="0.4" ixy="0.0" ixz="0.0" iyy="0.4" iyz="0.0" izz="0.2"/>-->
            <inertia ixx="1e-3" iyy="1e-3" izz="1e-3"/>
        </inertial>
    </link>
    <joint name="1_motor6link_to_penholder" type="fixed">
        <parent link="1_motor6link"/>
        <child link="1_penholder"/>
        <origin xyz=".0 .030 .0"/>
    </joint>
    <link name="1_penholder">
        <visual>
            <origin rpy="0 0 0" xyz="0 -0.001 0"/>
            <geometry>
                <box size="0.024 0.004 0.02"/>
            </geometry>
            <material name="white"/>
        </visual>
        <collision>
            <origin rpy="0 0 0" xyz="0 -0.001 0"/>
            <geometry>
                <box size="0.024 0.004 0.02"/>
            </geometry>
        </collision>
        <visual>
            <origin rpy="0 0 0" xyz="0 0.007 0"/>
            <geometry>
                <cylinder length="0.02" radius="0.007"/>
            </geometry>
            <material name="white"/>
        </visual>
        <collision>
            <origin rpy="0 0 0" xyz="0 0.007 0"/>
            <geometry>
                <cylinder length="0.02" radius="0.007"/>
            </geometry>
        </collision>
        <inertial>
            <mass value=".004"/>
            <inertia ixx="1e-5" iyy="1e-5" izz="1e-5"/>
            <!--<inertia ixx="0.4" ixy="0.0" ixz="0.0" iyy="0.4" iyz="0.0" izz="0.2"/>-->
        </inertial>
    </link>
    <joint name="1_penholder_to_upperpen" type="fixed">
        <parent link="1_penholder"/>
        <child link="1_upperpen"/>
        <origin xyz=".0 .007 .01"/>
    </joint>
    <link name="1_upperpen">
        <visual>
            <origin rpy="0 0 0" xyz="0 0 0.0675"/>
            <geometry>
                <cylinder length="0.135" radius="0.0035"/>
            </geometry>
            <material name="red"/>
        </visual>
        <collision>
            <origin rpy="0 0 0" xyz="0 0 0.0675"/>
            <geometry>
                <cylinder length="0.135" radius="0.0035"/>
            </geometry>
        </collision>
        <inertial>
            <mass value=".003"/>
            <inertia ixx="1e-5" iyy="1e-5" izz="1e-5"/>
            <!--<inertia ixx="0.4" ixy="0.0" ixz="0.0" iyy="0.4" iyz="0.0" izz="0.2"/>-->
        </inertial>
    </link>
    <joint name="1_penholder_to_lowerpen" type="fixed">
        <parent link="1_penholder"/>
        <child link="1_lowerpen"/>
        <origin xyz=".0 .007 -.01"/>
    </joint>
    <link name="1_lowerpen">
        <visual>
            <origin rpy="0 0 0" xyz="0 0 -0.0075"/>
            <geometry>
                <cylinder length="0.015" radius="0.0035"/>
            </geometry>
            <material name="red"/>
        </visual>
        <collision>
            <origin rpy="0 0 0" xyz="0 0 -0.0075"/>
            <geometry>
                <cylinder length="0.015" radius="0.0035"/>
            </geometry>
        </collision>
        <inertial>
            <mass value=".002"/>
            <inertia ixx="1e-5" iyy="1e-5" izz="1e-5"/>
        </inertial>
    </link>
</robot>
