<?xml version="1.0" ?>
<robot name="macros" xmlns:xacro="http://www.ros.org/wiki/xacro">
    <xacro:property name="pi" value="3.14159265359"/>
    <xacro:property name="pihalf" value="${pi/2}"/>

    <material name="white">
        <color rgba="1 1 1 1"/>
    </material>

    <material name="black">
        <color rgba="0 0 0 1"/>
    </material>
    <material name="red">
        <color rgba="1 0 0 1"/>
    </material>

    <xacro:macro name="cylinder2" params="length radius color:=white
                                        rotx:=0 roty:=0 rotz:=0
                                        posx:=0 posy:=0 posz:=0 ">
        <visual>
            <origin rpy="${rotx} ${roty} ${rotz}" xyz="${posx} ${posy} ${posz}"/>
            <geometry>
                <cylinder length="${length}" radius="${radius}"/>
            </geometry>
            <material name="${color}"/>
        </visual>
        <collision>
            <origin rpy="${rotx} ${roty} ${rotz}" xyz="${posx} ${posy} ${posz}"/>
            <geometry>
                <cylinder length="${length}" radius="${radius}"/>
            </geometry>
        </collision>
    </xacro:macro>


    <xacro:macro name="motor" params="rotx:=0 roty:=0 rotz:=0
                                    posx:=0 posy:=0 posz:=0 weird_mass:=0">
        <visual>
            <origin rpy="${rotx} ${roty} ${rotz}" xyz="${posx} ${posy} ${posz}"/>
            <geometry>
                <box size=".024 .035 .027"/>
            </geometry>
            <material name="black"/>
        </visual>
        <collision>
            <origin rpy="${rotx} ${roty} ${rotz}" xyz="${posx} ${posy} ${posz}"/>
            <geometry>
                <box size=".024 .035 .027"/>
            </geometry>
        </collision>
        <inertial>
            <!--ACTUAL MASS-->
            <!--<mass value=".017"/>-->

            <xacro:unless value="${weird_mass == 1}">
                <!--NORMAL WORKING MASS-->
                <mass value=".1"/>
            </xacro:unless>

            <xacro:if value="${weird_mass == 1}">
                <!--ACTUAL MASS-->
                <mass value="1.7"/>
            </xacro:if>

            <!--<inertia ixx="0.4" ixy="0.0" ixz="0.0" iyy="0.4" iyz="0.0" izz="0.2"/>-->
            <inertia ixx="1e-3" iyy="1e-3" izz="1e-3"/>
        </inertial>
    </xacro:macro>

    <xacro:macro name="big_motor" params="prefix motor axis prevlink backlash_on
                                            nextlink_on nextlink_val:=0
                                            rotx:=0 roty:=0 rotz:=0
                                            rotxn:=0 rotyn:=0 rotzn:=0
                                            posx:=0 posy:=0 posz:=0 backlash_val:=0">
        <xacro:if value="${backlash_on}">
            <joint name="${prefix}_motor${motor}backlash" type="revolute">
                <limit lower="-${backlash_val}" upper="${backlash_val}"/>
                <dynamics damping="100.0" friction="100.0"/>
                <parent link="${prefix}_${prevlink}"/>
                <child link="${prefix}_motor${motor}wheel"/>
                <axis xyz="${axis}"/>
                <origin rpy="${rotx} ${roty} ${rotz}" xyz="${posx} ${posy} ${posz}"/>
            </joint>
        </xacro:if>

        <xacro:unless value="${backlash_on}">
            <joint name="${prefix}_motor${motor}backlash" type="fixed">
                <parent link="${prefix}_${prevlink}"/>
                <child link="${prefix}_motor${motor}wheel"/>
                <origin rpy="${rotx} ${roty} ${rotz}" xyz="${posx} ${posy} ${posz}"/>
            </joint>
        </xacro:unless>

        <link name="${prefix}_motor${motor}wheel">
            <xacro:cylinder2 length=".2" radius="0.8" color="red" posz=".1"/>
            <inertial>
                <mass value="0.2"/>
                <inertia ixx="1" iyy="1" izz="1"/>
            </inertial>
        </link>

        <joint name="${prefix}_motor${motor}joint" type="revolute">
            <parent link="${prefix}_motor${motor}wheel"/>
            <child link="${prefix}_motor${motor}link"/>
            <origin xyz="0 0 .2"/>
            <dynamics damping="100.0" friction="100.0"/>
            <limit lower="-${pihalf}" upper="${pihalf}"/>
            <axis xyz="${axis}"/>
        </joint>

        <link name="${prefix}_motor${motor}link">
            <visual>
                <origin xyz="0 .95 1.25"/>
                <geometry>
                    <box size="2.4 3.5 2.5"/>
                </geometry>
                <material name="black"/>
            </visual>
            <collision>
                <origin xyz="0 .95 1.25"/>
                <geometry>
                    <box size="2.4 3.5 2.5"/>
                </geometry>
            </collision>
            <inertial>
                <!--<mass value="1.7"/>-->
                <mass value="0.7"/>
                <inertia ixx="0.55" iyy="0.76" izz="0.85"/>
                <!--<inertia ixx="2.55" iyy="2.76" izz="1.85"/>-->
            </inertial>
        </link>

        <xacro:if value="${nextlink_on}">
            <joint name="${prefix}_motor${motor}link_to_${nextlink_val}" type="fixed">
                <parent link="${prefix}_motor${motor}link"/>
                <child link="${prefix}_${nextlink_val}"/>
                <origin rpy="${rotxn} -${pihalf + rotyn} -${pihalf + rotzn}" xyz="0 1.9 1.3"/>
            </joint>

        </xacro:if>


    </xacro:macro>

    <xacro:macro name="box2" params="sizex sizey sizez color:=white nocoll:=0
                                    rotx:=0 roty:=0 rotz:=0
                                    posx:=0 posy:=0 posz:=0 ">
        <visual>
            <origin rpy="${rotx} ${roty} ${rotz}" xyz="${posx} ${posy} ${posz}"/>
            <geometry>
                <box size="${sizex} ${sizey} ${sizez}"/>
            </geometry>
            <material name="${color}"/>
        </visual>

        <xacro:unless value="${nocoll == 1}">
            <collision>
                <origin rpy="${rotx} ${roty} ${rotz}" xyz="${posx} ${posy} ${posz}"/>
                <geometry>
                    <box size="${sizex} ${sizey} ${sizez}"/>
                </geometry>
            </collision>
        </xacro:unless>
    </xacro:macro>

    <xacro:macro name="blash" params="backlash">
        <xacro:if value="${backlash == 1}">
            <dynamics damping=".1"/>
            <!--friction="50.0"-->
        </xacro:if>
    </xacro:macro>

    <xacro:macro name="trueblash" params="prefix backlash motor nextlink axis">
        <link name="${prefix}_motor${motor}backlashbody">
            <xacro:box2 sizex=".01" sizey=".01" sizez=".01" nocoll="0" color="red"/>
            <inertial>
                <mass value=".1"/>
                <inertia ixx="1e-3" iyy="1e-3" izz="1e-3"/>
            </inertial>
        </link>

        <joint name="${prefix}_motor${motor}backlash" type="revolute">
            <limit lower="-${backlash}" upper="${backlash}"/>
            <parent link="${prefix}_motor${motor}backlashbody"/>
            <child link="${nextlink}"/>
            <axis xyz="${axis}"/>
        </joint>
    </xacro:macro>
</robot>