<?xml version="1.0" ?>
<robot name="ergojr-base" xmlns:xacro="http://www.ros.org/wiki/xacro">
    <xacro:include filename="ergojr-macros.xacro.xml"/>

    <xacro:macro name="ergojr" params="prefix:=1 rotx_base:=0 roty_base:=0 rotz_base:=0
                                        posx_base:=0 posy_base:=0 posz_base:=0
                                        backlash_on:=1 backlash_val:=.1
                                        damping friction weight:=1 inertia:=1">

        <link name="${prefix}_anchor"/>

        <joint name="${prefix}_anchor_to_base" type="fixed">
            <parent link="${prefix}_anchor"/>
            <child link="${prefix}_base"/>
            <origin xyz="${posx_base} ${posy_base} ${posz_base}" rpy="${rotx_base} ${roty_base} ${rotz_base}"/>
        </joint>

        <link name="${prefix}_base">
            <xacro:cylinder2 length="0.05" radius="0.75" posz=".025"/>
            <inertial>
                <mass value="${.38 * weight}"/>
                <inertia ixx="${0.1 * inertia}" iyy="${0.1 * inertia}" izz="${0.1 * inertia}"/>
            </inertial>
        </link>

        <joint name="${prefix}_base_to_static" type="fixed">
            <parent link="${prefix}_base"/>
            <child link="${prefix}_static_first_link"/>
            <origin xyz="0 .38 0.05"/>
        </joint>

        <link name="${prefix}_static_first_link">
            <xacro:cylinder2 length="0.03" radius=".275" posz=".015"/>
            <inertial>
                <mass value="${.11 * weight}"/>
                <inertia ixx="${1e-4 * inertia}" iyy="${1e-4 * inertia}" izz="${1e-4 * inertia}"/>
            </inertial>
        </link>

        <joint name="${prefix}_motor1_to_static" type="fixed">
            <parent link="${prefix}_static_first_link"/>
            <child link="${prefix}_motor1link"/>
            <origin xyz="0 -.10 .03"/>
        </joint>

        <link name="${prefix}_motor1link">
            <visual>
                <origin rpy="0 0 0" xyz="0 0 .125"/>
                <geometry>
                    <box size=".24 .35 .25"/>
                </geometry>
                <material name="black"/>
            </visual>
            <collision>
                <origin rpy="0 0 0" xyz="0 0 .125"/>
                <geometry>
                    <box size=".24 .35 .25"/>
                </geometry>
            </collision>
            <inertial>
                <mass value="${.17 * weight}"/>
                <inertia ixx="${.255 * inertia}" iyy="${.276 * inertia}" izz="${.185 * inertia}"/>
            </inertial>
        </link>
        <joint name="${prefix}_motor1joint" type="revolute">
            <parent link="${prefix}_motor1link"/>
            <child link="${prefix}_motor1wheel"/>
            <origin rpy="0 0 0" xyz="0 .095 .25"/>
            <dynamics damping="${damping}" friction="${friction}"/>
            <limit lower="-${pihalf}" upper="${pihalf}"/>
            <axis xyz="0 0 1"/>
        </joint>
        <link name="${prefix}_motor1wheel">
            <xacro:cylinder2 length=".02" radius=".08" color="red" posz=".01"/>
            <inertial>
                <mass value="${.02 * weight}"/>
                <inertia ixx="${.1 * inertia}" iyy="${.1 * inertia}" izz="${.1 * inertia}"/>
            </inertial>
        </link>
        <xacro:if value="${backlash_on}">
            <joint name="${prefix}_motor1backlash" type="revolute">
                <limit lower="-${backlash_val}" upper="${backlash_val}"/>
                <dynamics damping="${damping}" friction="${friction}"/>
                <parent link="${prefix}_motor1wheel"/>
                <child link="${prefix}_link1_bottom"/>
                <axis xyz="0 0 1"/>
                <origin xyz="0 0 0.02"/>
            </joint>
        </xacro:if>

        <xacro:unless value="${backlash_on}">
            <joint name="${prefix}_motor1backlash" type="fixed">
                <parent link="${prefix}_motor1wheel"/>
                <child link="${prefix}_link1_bottom"/>
                <origin xyz="0 0 0.02"/>
            </joint>
        </xacro:unless>


        <link name="${prefix}_link1_bottom">
            <xacro:box2 sizex=".34" sizey=".2" sizez=".02" posz=".01"/>
            <xacro:box2 sizex=".02" sizey=".2" sizez=".345" posz=".1725" posx="-.16"/>
            <xacro:box2 sizex=".05" sizey=".2" sizez=".345" posz=".1725" posx=".145"/>

            <inertial>
                <mass value="${.05 * weight}"/>
                <inertia ixx="${1e-4 * inertia}" iyy="${1e-4 * inertia}" izz="${1e-4 * inertia}"/>
            </inertial>
        </link>

        <xacro:big_motor2 posx="-.15" posz=".24" rotx="${pihalf}" rotz="${pihalf}"
                          motor="2" axis="0 0 1" prefix="1" backlash_on="${backlash_on}"
                          backlash_val="${backlash_val}" prevlink="link1_bottom"
                          nextlink_on="1" nextlink_val="motor2bridge3"
                          damping="${damping}" friction="${friction}" weight="${weight}" inertia="${inertia}"/>

        <link name="${prefix}_motor2bridge3">
            <xacro:box2 sizex=".02" sizey=".2" sizez=".45" posx="-.16" posz=".225"/>
            <xacro:box2 sizex=".05" sizey=".2" sizez=".45" posx=".145" posz=".225"/>
            <inertial>
                <mass value="${.045 * weight}"/>
                <inertia ixx="${1e-4 * inertia}" iyy="${1e-4 * inertia}" izz="${1e-4 * inertia}"/>
            </inertial>
        </link>

        <xacro:big_motor2 posx="-.15" posz=".35" rotx="${pihalf}" rotz="${pihalf}"
                          motor="3" axis="0 0 1" prefix="1" backlash_on="${backlash_on}"
                          backlash_val="${backlash_val}" prevlink="motor2bridge3"
                          nextlink_on="1" nextlink_val="motor3bridge4"
                          damping="${damping}" friction="${friction}" weight="${weight}" inertia="${inertia}"/>


        <link name="${prefix}_motor3bridge4">
            <xacro:box2 sizex=".27" sizey=".2" sizez=".02" posz=".09" posx="-.015"/>
            <inertial>
                <mass value="${.01 * weight}"/>
                <inertia ixx="${1e-4 * inertia}" iyy="${1e-4 * inertia}" izz="${1e-4 * inertia}"/>
            </inertial>
        </link>

        <xacro:big_motor2 posy="0" posz=".10"
                          motor="4" axis="0 0 1" prefix="1" backlash_on="${backlash_on}"
                          backlash_val="${backlash_val}" prevlink="motor3bridge4"
                          nextlink_on="1" nextlink_val="motor4bridge5"
                          rotxn="${pi}" rotyn="${pihalf}" rotzn="${pihalf}"
                          damping="${damping}" friction="${friction}" weight="${weight}" inertia="${inertia}"/>

        <link name="${prefix}_motor4bridge5">
            <xacro:box2 sizex=".02" sizey=".45" sizez=".2" posx="-.16" posy=".225"/>
            <xacro:box2 sizex=".03" sizey=".05" sizez=".2" posx="-.135" posy=".025"/>
            <xacro:box2 sizex=".04" sizey=".45" sizez=".2" posx=".14" posy=".225"/>
            <inertial>
                <mass value="${.045 * weight}"/>
                <inertia ixx="${1e-4 * inertia}" iyy="${1e-4 * inertia}" izz="${1e-4 * inertia}"/>
            </inertial>
        </link>

        <xacro:big_motor2 posx="-.15" posy=".35" posz="0" roty="${pihalf}"
                          motor="5" axis="0 0 1" prefix="1" backlash_on="${backlash_on}"
                          backlash_val="${backlash_val}" prevlink="motor4bridge5"
                          nextlink_on="1" nextlink_val="motor5bridge6" rotxn="${pihalf}"
                          damping="${damping}" friction="${friction}" weight="${weight}" inertia="${inertia}"/>

        <link name="${prefix}_motor5bridge6">
            <xacro:box2 sizex=".02" sizey=".45" sizez=".2" posx="-.16" posy=".225"/>
            <xacro:box2 sizex=".04" sizey=".45" sizez=".2" posx=".14" posy=".225"/>
            <inertial>
                <mass value="${.045 * weight}"/>
                <inertia ixx="${1e-4 * inertia}" iyy="${1e-4 * inertia}" izz="${1e-4 * inertia}"/>
            </inertial>
        </link>

        <xacro:big_motor2 posx="-.15" posy=".35" posz="0" roty="${pihalf}"
                          motor="6" axis="0 0 1" prefix="1" backlash_on="${backlash_on}"
                          backlash_val="${backlash_val}" prevlink="motor5bridge6"
                          nextlink_on="0" damping="${damping}" friction="${friction}"
                          weight="${weight}" inertia="${inertia}"/>

    </xacro:macro>

</robot>
