<?xml version="1.0" ?>
<robot name="puck" xmlns:xacro="http://www.ros.org/wiki/xacro">
  <material name="white">
    <color rgba="1 1 1 1"/>
  </material>
  <material name="black">
    <color rgba="0 0 0 1"/>
  </material>
  <material name="red">
    <color rgba="1 0 0 1"/>
  </material>
  <link name="2_anchor">
    <inertial>
      <mass value="1"/>
      <inertia ixx="1" iyy="1" izz="1"/>
    </inertial>
  </link>
  <joint name="2_puck_to_world" type="prismatic">
    <parent link="2_anchor"/>
    <child link="2_puck_y"/>
    <axis xyz="0 1 0"/>
    <limit effort="0.0" lower="-1" upper="1" velocity="1000.0"/>
  </joint>
  <link name="2_puck_y">
    <inertial>
      <mass value="0.1"/>
      <inertia ixx="1.7500000000000002e-05" ixy="0" ixz="0" iyy="1.7500000000000002e-05" iyz="0" izz="2e-05"/>
      <origin rpy="0 0 0" xyz="0 0 0"/>
    </inertial>
  </link>
  <joint name="2_puck_y_to_z" type="prismatic">
    <parent link="2_puck_y"/>
    <child link="2_puck"/>
    <axis xyz="1 0 0"/>
    <limit effort="0.0" lower="-1" upper="1" velocity="1000.0"/>
  </joint>
  <!--    <link name="2_puck_z">-->
  <!--        <inertial>-->
  <!--            <mass value="0.01"/>-->
  <!--            <inertia ixx="0.2125" ixy="-0.005" ixz="0.0225" iyy="0.205" iyz="0.045" izz="0.0125"/>-->
  <!--            <origin rpy="0 0 0" xyz="0 0 0"/>-->
  <!--        </inertial>-->
  <!--    </link>-->
  <!--    <joint name="2_puck_z_to_puck" type="continuous">-->
  <!--        <parent link="2_puck_z"/>-->
  <!--        <child link="2_puck"/>-->
  <!--        <axis xyz="0 0 1"/>-->
  <!--    </joint>-->
  <link name="2_puck">
    <visual>
      <origin rpy="0 0 0" xyz="0 0 0.015"/>
      <geometry>
        <cylinder length="0.03" radius="0.02"/>
      </geometry>
      <material name="red"/>
    </visual>
    <collision>
      <origin rpy="0 0 0" xyz="0 0 0.015"/>
      <geometry>
        <cylinder length="0.03" radius="0.02"/>
      </geometry>
    </collision>
    <inertial>
      <mass value="0.1"/>
      <inertia ixx="1.7500000000000002e-05" ixy="0" ixz="0" iyy="1.7500000000000002e-05" iyz="0" izz="2e-05"/>
      <origin rpy="0 0 0" xyz="0 0 0"/>
    </inertial>
  </link>
</robot>
