<?xml version="1.0" ?>
<robot name="ergojr-penholder" xmlns:xacro="http://www.ros.org/wiki/xacro">
  <material name="white">
    <color rgba="1 1 1 1"/>
  </material>
  <material name="black">
    <color rgba="0 0 0 1"/>
  </material>
  <material name="red">
    <color rgba="1 0 0 1"/>
  </material>
  <material name="blue">
    <color rgba="0 0 1 1"/>
  </material>
  <material name="white">
    <color rgba="1 1 1 1"/>
  </material>
  <material name="black">
    <color rgba="0 0 0 1"/>
  </material>
  <material name="red">
    <color rgba="1 0 0 1"/>
  </material>
  <material name="blue">
    <color rgba="0 0 1 1"/>
  </material>
  <link name="1_anchor">
    <inertial>
      <mass value="1"/>
      <inertia ixx="1" iyy="1" izz="1"/>
    </inertial>
  </link>
  <joint name="1_anchor_to_base" type="fixed">
    <parent link="1_anchor"/>
    <child link="1_base"/>
    <origin rpy="0 0 0" xyz="0 0 0"/>
  </joint>
  <link name="1_base">
    <visual>
      <origin rpy="0 0 0" xyz="0 0 0.25"/>
      <geometry>
        <cylinder length="0.5" radius="7.5"/>
      </geometry>
      <material name="white"/>
    </visual>
    <collision>
      <origin rpy="0 0 0" xyz="0 0 0.25"/>
      <geometry>
        <cylinder length="0.5" radius="7.5"/>
      </geometry>
    </collision>
    <inertial>
      <mass value="1.9"/>
      <inertia ixx="0.5" iyy="0.5" izz="0.5"/>
    </inertial>
  </link>
  <joint name="1_base_to_static" type="fixed">
    <parent link="1_base"/>
    <child link="1_static_first_link"/>
    <origin xyz="0 3.8 0.5"/>
  </joint>
  <link name="1_static_first_link">
    <visual>
      <origin rpy="0 0 0" xyz="0 0 0.15"/>
      <geometry>
        <cylinder length="0.3" radius="2.75"/>
      </geometry>
      <material name="white"/>
    </visual>
    <collision>
      <origin rpy="0 0 0" xyz="0 0 0.15"/>
      <geometry>
        <cylinder length="0.3" radius="2.75"/>
      </geometry>
    </collision>
    <inertial>
      <mass value="0.55"/>
      <inertia ixx="0.0005" iyy="0.0005" izz="0.0005"/>
    </inertial>
  </link>
  <joint name="1_motor1_to_static" type="fixed">
    <parent link="1_static_first_link"/>
    <child link="1_motor1link"/>
    <origin xyz="0 -1.0 .3"/>
  </joint>
  <link name="1_motor1link">
    <visual>
      <origin rpy="0 0 0" xyz="0 0 1.25"/>
      <geometry>
        <box size="2.4 3.5 2.5"/>
      </geometry>
      <material name="black"/>
    </visual>
    <collision>
      <origin rpy="0 0 0" xyz="0 0 1.25"/>
      <geometry>
        <box size="2.4 3.5 2.5"/>
      </geometry>
    </collision>
    <inertial>
      <mass value="0.85"/>
      <inertia ixx="1.275" iyy="1.38" izz="0.925"/>
    </inertial>
  </link>
  <joint name="1_motor1joint" type="revolute">
    <parent link="1_motor1link"/>
    <child link="1_motor1wheel"/>
    <origin rpy="0 0 0" xyz="0 .95 2.5"/>
    <dynamics damping="100.0" friction="10.0"/>
    <limit lower="-1.570796326795" upper="1.570796326795"/>
    <axis xyz="0 0 1"/>
  </joint>
  <link name="1_motor1wheel">
    <visual>
      <origin rpy="0 0 0" xyz="0 0 0.1"/>
      <geometry>
        <cylinder length="0.2" radius="0.8"/>
      </geometry>
      <material name="red"/>
    </visual>
    <collision>
      <origin rpy="0 0 0" xyz="0 0 0.1"/>
      <geometry>
        <cylinder length="0.2" radius="0.8"/>
      </geometry>
    </collision>
    <inertial>
      <mass value="0.1"/>
      <inertia ixx="0.5" iyy="0.5" izz="0.5"/>
    </inertial>
  </link>
  <joint name="1_motor1backlash" type="revolute">
    <limit lower="-0.0" upper="0.0"/>
    <dynamics damping="100.0" friction="10.0"/>
    <parent link="1_motor1wheel"/>
    <child link="1_link1_bottom"/>
    <axis xyz="0 0 1"/>
    <origin xyz="0 0 0.2"/>
  </joint>
  <link name="1_link1_bottom">
    <visual>
      <origin rpy="0 0 0" xyz="0 0 0.1"/>
      <geometry>
        <box size="3.4 2.0 0.2"/>
      </geometry>
      <material name="white"/>
    </visual>
    <collision>
      <origin rpy="0 0 0" xyz="0 0 0.1"/>
      <geometry>
        <box size="3.4 2.0 0.2"/>
      </geometry>
    </collision>
    <visual>
      <origin rpy="0 0 0" xyz="-1.6 0 1.725"/>
      <geometry>
        <box size="0.2 2.0 3.45"/>
      </geometry>
      <material name="white"/>
    </visual>
    <collision>
      <origin rpy="0 0 0" xyz="-1.6 0 1.725"/>
      <geometry>
        <box size="0.2 2.0 3.45"/>
      </geometry>
    </collision>
    <visual>
      <origin rpy="0 0 0" xyz="1.45 0 1.725"/>
      <geometry>
        <box size="0.5 2.0 3.45"/>
      </geometry>
      <material name="white"/>
    </visual>
    <collision>
      <origin rpy="0 0 0" xyz="1.45 0 1.725"/>
      <geometry>
        <box size="0.5 2.0 3.45"/>
      </geometry>
    </collision>
    <inertial>
      <mass value="0.25"/>
      <inertia ixx="0.0005" iyy="0.0005" izz="0.0005"/>
    </inertial>
  </link>
  <joint name="1_motor2backlash" type="revolute">
    <limit lower="-0.0" upper="0.0"/>
    <dynamics damping="10" friction="10"/>
    <parent link="1_link1_bottom"/>
    <child link="1_motor2wheel"/>
    <axis xyz="0 0 1"/>
    <origin rpy="1.570796326795 0 1.570796326795" xyz="-1.5 0 2.4"/>
  </joint>
  <link name="1_motor2wheel">
    <visual>
      <origin rpy="0 0 0" xyz="0 0 0.1"/>
      <geometry>
        <cylinder length="0.2" radius="0.8"/>
      </geometry>
      <material name="red"/>
    </visual>
    <collision>
      <origin rpy="0 0 0" xyz="0 0 0.1"/>
      <geometry>
        <cylinder length="0.2" radius="0.8"/>
      </geometry>
    </collision>
    <inertial>
      <mass value="0.1"/>
      <inertia ixx="0.5" iyy="0.5" izz="0.5"/>
    </inertial>
  </link>
  <joint name="1_motor2joint" type="revolute">
    <parent link="1_motor2wheel"/>
    <child link="1_motor2link"/>
    <origin xyz="0 0 .2"/>
    <dynamics damping="10" friction="10"/>
    <limit lower="-1.570796326795" upper="1.570796326795"/>
    <axis xyz="0 0 1"/>
  </joint>
  <link name="1_motor2link">
    <visual>
      <origin xyz="0 .95 1.25"/>
      <geometry>
        <box size="2.4 3.5 2.5"/>
      </geometry>
      <material name="black"/>
    </visual>
    <collision>
      <origin xyz="0 .95 1.25"/>
      <geometry>
        <box size="2.4 3.5 2.5"/>
      </geometry>
    </collision>
    <inertial>
      <mass value="0.35"/>
      <inertia ixx="0.775" iyy="0.88" izz="0.425"/>
      <!--<mass value="${0.7 * weight}"/>-->
      <!--<inertia ixx="${2.55 * weight}" iyy="${2.76 * weight}" izz="${1.85 * weight}"/>-->
    </inertial>
  </link>
  <joint name="1_motor2link_to_motor2bridge3" type="fixed">
    <parent link="1_motor2link"/>
    <child link="1_motor2bridge3"/>
    <origin rpy="0 -1.570796326795 -1.570796326795" xyz="0 1.9 1.3"/>
  </joint>
  <link name="1_motor2bridge3">
    <visual>
      <origin rpy="0 0 0" xyz="-1.6 0 2.25"/>
      <geometry>
        <box size="0.2 2.0 4.5"/>
      </geometry>
      <material name="white"/>
    </visual>
    <collision>
      <origin rpy="0 0 0" xyz="-1.6 0 2.25"/>
      <geometry>
        <box size="0.2 2.0 4.5"/>
      </geometry>
    </collision>
    <visual>
      <origin rpy="0 0 0" xyz="1.45 0 2.25"/>
      <geometry>
        <box size="0.5 2.0 4.5"/>
      </geometry>
      <material name="white"/>
    </visual>
    <collision>
      <origin rpy="0 0 0" xyz="1.45 0 2.25"/>
      <geometry>
        <box size="0.5 2.0 4.5"/>
      </geometry>
    </collision>
    <inertial>
      <mass value="0.225"/>
      <inertia ixx="0.0005" iyy="0.0005" izz="0.0005"/>
    </inertial>
  </link>
  <joint name="1_motor3backlash" type="revolute">
    <limit lower="-0.0" upper="0.0"/>
    <dynamics damping="10" friction="10"/>
    <parent link="1_motor2bridge3"/>
    <child link="1_motor3wheel"/>
    <axis xyz="0 0 1"/>
    <origin rpy="1.570796326795 0 1.570796326795" xyz="-1.5 0 3.5"/>
  </joint>
  <link name="1_motor3wheel">
    <visual>
      <origin rpy="0 0 0" xyz="0 0 0.1"/>
      <geometry>
        <cylinder length="0.2" radius="0.8"/>
      </geometry>
      <material name="red"/>
    </visual>
    <collision>
      <origin rpy="0 0 0" xyz="0 0 0.1"/>
      <geometry>
        <cylinder length="0.2" radius="0.8"/>
      </geometry>
    </collision>
    <inertial>
      <mass value="0.1"/>
      <inertia ixx="0.5" iyy="0.5" izz="0.5"/>
    </inertial>
  </link>
  <joint name="1_motor3joint" type="revolute">
    <parent link="1_motor3wheel"/>
    <child link="1_motor3link"/>
    <origin xyz="0 0 .2"/>
    <dynamics damping="10" friction="10"/>
    <limit lower="-1.570796326795" upper="1.570796326795"/>
    <axis xyz="0 0 1"/>
  </joint>
  <link name="1_motor3link">
    <visual>
      <origin xyz="0 .95 1.25"/>
      <geometry>
        <box size="2.4 3.5 2.5"/>
      </geometry>
      <material name="black"/>
    </visual>
    <collision>
      <origin xyz="0 .95 1.25"/>
      <geometry>
        <box size="2.4 3.5 2.5"/>
      </geometry>
    </collision>
    <inertial>
      <mass value="0.35"/>
      <inertia ixx="0.775" iyy="0.88" izz="0.425"/>
      <!--<mass value="${0.7 * weight}"/>-->
      <!--<inertia ixx="${2.55 * weight}" iyy="${2.76 * weight}" izz="${1.85 * weight}"/>-->
    </inertial>
  </link>
  <joint name="1_motor3link_to_motor3bridge4" type="fixed">
    <parent link="1_motor3link"/>
    <child link="1_motor3bridge4"/>
    <origin rpy="0 -1.570796326795 -1.570796326795" xyz="0 1.9 1.3"/>
  </joint>
  <link name="1_motor3bridge4">
    <visual>
      <origin rpy="0 0 0" xyz="-0.15 0 0.9"/>
      <geometry>
        <box size="2.7 2.0 0.2"/>
      </geometry>
      <material name="white"/>
    </visual>
    <collision>
      <origin rpy="0 0 0" xyz="-0.15 0 0.9"/>
      <geometry>
        <box size="2.7 2.0 0.2"/>
      </geometry>
    </collision>
    <inertial>
      <mass value="0.05"/>
      <inertia ixx="0.0005" iyy="0.0005" izz="0.0005"/>
    </inertial>
  </link>
  <joint name="1_motor4backlash" type="revolute">
    <limit lower="-0.0" upper="0.0"/>
    <dynamics damping="10" friction="10"/>
    <parent link="1_motor3bridge4"/>
    <child link="1_motor4wheel"/>
    <axis xyz="0 0 1"/>
    <origin rpy="0 0 0" xyz="0 0 1.0"/>
  </joint>
  <link name="1_motor4wheel">
    <visual>
      <origin rpy="0 0 0" xyz="0 0 0.1"/>
      <geometry>
        <cylinder length="0.2" radius="0.8"/>
      </geometry>
      <material name="red"/>
    </visual>
    <collision>
      <origin rpy="0 0 0" xyz="0 0 0.1"/>
      <geometry>
        <cylinder length="0.2" radius="0.8"/>
      </geometry>
    </collision>
    <inertial>
      <mass value="0.1"/>
      <inertia ixx="0.5" iyy="0.5" izz="0.5"/>
    </inertial>
  </link>
  <joint name="1_motor4joint" type="revolute">
    <parent link="1_motor4wheel"/>
    <child link="1_motor4link"/>
    <origin xyz="0 0 .2"/>
    <dynamics damping="10" friction="10"/>
    <limit lower="-1.570796326795" upper="1.570796326795"/>
    <axis xyz="0 0 1"/>
  </joint>
  <link name="1_motor4link">
    <visual>
      <origin xyz="0 .95 1.25"/>
      <geometry>
        <box size="2.4 3.5 2.5"/>
      </geometry>
      <material name="black"/>
    </visual>
    <collision>
      <origin xyz="0 .95 1.25"/>
      <geometry>
        <box size="2.4 3.5 2.5"/>
      </geometry>
    </collision>
    <inertial>
      <mass value="0.35"/>
      <inertia ixx="0.775" iyy="0.88" izz="0.425"/>
      <!--<mass value="${0.7 * weight}"/>-->
      <!--<inertia ixx="${2.55 * weight}" iyy="${2.76 * weight}" izz="${1.85 * weight}"/>-->
    </inertial>
  </link>
  <joint name="1_motor4link_to_motor4bridge5" type="fixed">
    <parent link="1_motor4link"/>
    <child link="1_motor4bridge5"/>
    <origin rpy="3.14159265359 -3.14159265359 -3.14159265359" xyz="0 1.9 1.3"/>
  </joint>
  <link name="1_motor4bridge5">
    <visual>
      <origin rpy="0 0 0" xyz="-1.6 2.25 0"/>
      <geometry>
        <box size="0.2 4.5 2.0"/>
      </geometry>
      <material name="white"/>
    </visual>
    <collision>
      <origin rpy="0 0 0" xyz="-1.6 2.25 0"/>
      <geometry>
        <box size="0.2 4.5 2.0"/>
      </geometry>
    </collision>
    <visual>
      <origin rpy="0 0 0" xyz="-1.35 0.25 0"/>
      <geometry>
        <box size="0.3 0.5 2.0"/>
      </geometry>
      <material name="white"/>
    </visual>
    <collision>
      <origin rpy="0 0 0" xyz="-1.35 0.25 0"/>
      <geometry>
        <box size="0.3 0.5 2.0"/>
      </geometry>
    </collision>
    <visual>
      <origin rpy="0 0 0" xyz="1.4 2.25 0"/>
      <geometry>
        <box size="0.4 4.5 2.0"/>
      </geometry>
      <material name="white"/>
    </visual>
    <collision>
      <origin rpy="0 0 0" xyz="1.4 2.25 0"/>
      <geometry>
        <box size="0.4 4.5 2.0"/>
      </geometry>
    </collision>
    <inertial>
      <mass value="0.225"/>
      <inertia ixx="0.0005" iyy="0.0005" izz="0.0005"/>
    </inertial>
  </link>
  <joint name="1_motor5backlash" type="revolute">
    <limit lower="-0.0" upper="0.0"/>
    <dynamics damping="10" friction="10"/>
    <parent link="1_motor4bridge5"/>
    <child link="1_motor5wheel"/>
    <axis xyz="0 0 1"/>
    <origin rpy="0 1.570796326795 0" xyz="-1.5 3.5 0"/>
  </joint>
  <link name="1_motor5wheel">
    <visual>
      <origin rpy="0 0 0" xyz="0 0 0.1"/>
      <geometry>
        <cylinder length="0.2" radius="0.8"/>
      </geometry>
      <material name="red"/>
    </visual>
    <collision>
      <origin rpy="0 0 0" xyz="0 0 0.1"/>
      <geometry>
        <cylinder length="0.2" radius="0.8"/>
      </geometry>
    </collision>
    <inertial>
      <mass value="0.1"/>
      <inertia ixx="0.5" iyy="0.5" izz="0.5"/>
    </inertial>
  </link>
  <joint name="1_motor5joint" type="revolute">
    <parent link="1_motor5wheel"/>
    <child link="1_motor5link"/>
    <origin xyz="0 0 .2"/>
    <dynamics damping="10" friction="10"/>
    <limit lower="-1.570796326795" upper="1.570796326795"/>
    <axis xyz="0 0 1"/>
  </joint>
  <link name="1_motor5link">
    <visual>
      <origin xyz="0 .95 1.25"/>
      <geometry>
        <box size="2.4 3.5 2.5"/>
      </geometry>
      <material name="black"/>
    </visual>
    <collision>
      <origin xyz="0 .95 1.25"/>
      <geometry>
        <box size="2.4 3.5 2.5"/>
      </geometry>
    </collision>
    <inertial>
      <mass value="0.35"/>
      <inertia ixx="0.775" iyy="0.88" izz="0.425"/>
      <!--<mass value="${0.7 * weight}"/>-->
      <!--<inertia ixx="${2.55 * weight}" iyy="${2.76 * weight}" izz="${1.85 * weight}"/>-->
    </inertial>
  </link>
  <joint name="1_motor5link_to_motor5bridge6" type="fixed">
    <parent link="1_motor5link"/>
    <child link="1_motor5bridge6"/>
    <origin rpy="1.570796326795 -1.570796326795 -1.570796326795" xyz="0 1.9 1.3"/>
  </joint>
  <link name="1_motor5bridge6">
    <visual>
      <origin rpy="0 0 0" xyz="-1.6 2.25 0"/>
      <geometry>
        <box size="0.2 4.5 2.0"/>
      </geometry>
      <material name="white"/>
    </visual>
    <collision>
      <origin rpy="0 0 0" xyz="-1.6 2.25 0"/>
      <geometry>
        <box size="0.2 4.5 2.0"/>
      </geometry>
    </collision>
    <visual>
      <origin rpy="0 0 0" xyz="1.4 2.25 0"/>
      <geometry>
        <box size="0.4 4.5 2.0"/>
      </geometry>
      <material name="white"/>
    </visual>
    <collision>
      <origin rpy="0 0 0" xyz="1.4 2.25 0"/>
      <geometry>
        <box size="0.4 4.5 2.0"/>
      </geometry>
    </collision>
    <inertial>
      <mass value="0.225"/>
      <inertia ixx="0.0005" iyy="0.0005" izz="0.0005"/>
    </inertial>
  </link>
  <joint name="1_motor6backlash" type="revolute">
    <limit lower="-0.0" upper="0.0"/>
    <dynamics damping="10" friction="10"/>
    <parent link="1_motor5bridge6"/>
    <child link="1_motor6wheel"/>
    <axis xyz="0 0 1"/>
    <origin rpy="0 1.570796326795 0" xyz="-1.5 3.5 0"/>
  </joint>
  <link name="1_motor6wheel">
    <visual>
      <origin rpy="0 0 0" xyz="0 0 0.1"/>
      <geometry>
        <cylinder length="0.2" radius="0.8"/>
      </geometry>
      <material name="red"/>
    </visual>
    <collision>
      <origin rpy="0 0 0" xyz="0 0 0.1"/>
      <geometry>
        <cylinder length="0.2" radius="0.8"/>
      </geometry>
    </collision>
    <inertial>
      <mass value="0.1"/>
      <inertia ixx="0.5" iyy="0.5" izz="0.5"/>
    </inertial>
  </link>
  <joint name="1_motor6joint" type="revolute">
    <parent link="1_motor6wheel"/>
    <child link="1_motor6link"/>
    <origin xyz="0 0 .2"/>
    <dynamics damping="10" friction="10"/>
    <limit lower="-1.570796326795" upper="1.570796326795"/>
    <axis xyz="0 0 1"/>
  </joint>
  <link name="1_motor6link">
    <visual>
      <origin xyz="0 .95 1.25"/>
      <geometry>
        <box size="2.4 3.5 2.5"/>
      </geometry>
      <material name="black"/>
    </visual>
    <collision>
      <origin xyz="0 .95 1.25"/>
      <geometry>
        <box size="2.4 3.5 2.5"/>
      </geometry>
    </collision>
    <inertial>
      <mass value="0.35"/>
      <inertia ixx="0.775" iyy="0.88" izz="0.425"/>
      <!--<mass value="${0.7 * weight}"/>-->
      <!--<inertia ixx="${2.55 * weight}" iyy="${2.76 * weight}" izz="${1.85 * weight}"/>-->
    </inertial>
  </link>
  <joint name="motor6link_to_penholder" type="fixed">
    <parent link="1_motor6link"/>
    <child link="penholder"/>
    <origin rpy="0 1.570796326795 0" xyz="0 3.0 1.25"/>
  </joint>
  <link name="penholder">
    <visual>
      <origin rpy="0 0 0" xyz="0 -0.1 0"/>
      <geometry>
        <box size="2.4 0.4 2.0"/>
      </geometry>
      <material name="white"/>
    </visual>
    <collision>
      <origin rpy="0 0 0" xyz="0 -0.1 0"/>
      <geometry>
        <box size="2.4 0.4 2.0"/>
      </geometry>
    </collision>
    <visual>
      <origin rpy="0 0 0" xyz="0 0.7 0"/>
      <geometry>
        <cylinder length="2.0" radius="0.7"/>
      </geometry>
      <material name="white"/>
    </visual>
    <collision>
      <origin rpy="0 0 0" xyz="0 0.7 0"/>
      <geometry>
        <cylinder length="2.0" radius="0.7"/>
      </geometry>
    </collision>
    <inertial>
      <mass value="0.2"/>
      <inertia ixx="0.0005" iyy="0.0005" izz="0.0005"/>
    </inertial>
  </link>
</robot>
