<?xml version="1.0" ?>
<robot name="ergojr-penholder" xmlns:xacro="http://www.ros.org/wiki/xacro">
  <material name="white">
    <color rgba="1 1 1 1"/>
  </material>
  <material name="black">
    <color rgba="0 0 0 1"/>
  </material>
  <material name="red">
    <color rgba="1 0 0 1"/>
  </material>
  <material name="white">
    <color rgba="1 1 1 1"/>
  </material>
  <material name="black">
    <color rgba="0 0 0 1"/>
  </material>
  <material name="red">
    <color rgba="1 0 0 1"/>
  </material>
  <link name="1_anchor"/>
  <joint name="1_anchor_to_base" type="fixed">
    <parent link="1_anchor"/>
    <child link="1_base"/>
    <origin rpy="0 0 0" xyz="0 0 0"/>
  </joint>
  <link name="1_base">
    <visual>
      <origin rpy="0 0 0" xyz="0 0 0.025"/>
      <geometry>
        <cylinder length="0.05" radius="0.75"/>
      </geometry>
      <material name="white"/>
    </visual>
    <collision>
      <origin rpy="0 0 0" xyz="0 0 0.025"/>
      <geometry>
        <cylinder length="0.05" radius="0.75"/>
      </geometry>
    </collision>
    <inertial>
      <mass value="0.38"/>
      <inertia ixx="0.1" iyy="0.1" izz="0.1"/>
    </inertial>
  </link>
  <joint name="1_base_to_static" type="fixed">
    <parent link="1_base"/>
    <child link="1_static_first_link"/>
    <origin xyz="0 .38 0.05"/>
  </joint>
  <link name="1_static_first_link">
    <visual>
      <origin rpy="0 0 0" xyz="0 0 0.015"/>
      <geometry>
        <cylinder length="0.03" radius="0.275"/>
      </geometry>
      <material name="white"/>
    </visual>
    <collision>
      <origin rpy="0 0 0" xyz="0 0 0.015"/>
      <geometry>
        <cylinder length="0.03" radius="0.275"/>
      </geometry>
    </collision>
    <inertial>
      <mass value="0.11"/>
      <inertia ixx="0.0001" iyy="0.0001" izz="0.0001"/>
    </inertial>
  </link>
  <joint name="1_motor1_to_static" type="fixed">
    <parent link="1_static_first_link"/>
    <child link="1_motor1link"/>
    <origin xyz="0 -.10 .03"/>
  </joint>
  <link name="1_motor1link">
    <visual>
      <origin rpy="0 0 0" xyz="0 0 .125"/>
      <geometry>
        <box size=".24 .35 .25"/>
      </geometry>
      <material name="black"/>
    </visual>
    <collision>
      <origin rpy="0 0 0" xyz="0 0 .125"/>
      <geometry>
        <box size=".24 .35 .25"/>
      </geometry>
    </collision>
    <inertial>
      <mass value="0.17"/>
      <inertia ixx="0.255" iyy="0.276" izz="0.185"/>
    </inertial>
  </link>
  <joint name="1_motor1joint" type="revolute">
    <parent link="1_motor1link"/>
    <child link="1_motor1wheel"/>
    <origin rpy="0 0 0" xyz="0 .095 .25"/>
    <dynamics damping="0.1" friction="0.1"/>
    <limit lower="-1.570796326795" upper="1.570796326795"/>
    <axis xyz="0 0 1"/>
  </joint>
  <link name="1_motor1wheel">
    <visual>
      <origin rpy="0 0 0" xyz="0 0 0.01"/>
      <geometry>
        <cylinder length="0.02" radius="0.08"/>
      </geometry>
      <material name="red"/>
    </visual>
    <collision>
      <origin rpy="0 0 0" xyz="0 0 0.01"/>
      <geometry>
        <cylinder length="0.02" radius="0.08"/>
      </geometry>
    </collision>
    <inertial>
      <mass value="0.02"/>
      <inertia ixx="0.1" iyy="0.1" izz="0.1"/>
    </inertial>
  </link>
  <joint name="1_motor1backlash" type="revolute">
    <limit lower="-0.1" upper="0.1"/>
    <dynamics damping="0.1" friction="0.1"/>
    <parent link="1_motor1wheel"/>
    <child link="1_link1_bottom"/>
    <axis xyz="0 0 1"/>
    <origin xyz="0 0 0.02"/>
  </joint>
  <link name="1_link1_bottom">
    <visual>
      <origin rpy="0 0 0" xyz="0 0 0.01"/>
      <geometry>
        <box size="0.34 0.2 0.02"/>
      </geometry>
      <material name="white"/>
    </visual>
    <collision>
      <origin rpy="0 0 0" xyz="0 0 0.01"/>
      <geometry>
        <box size="0.34 0.2 0.02"/>
      </geometry>
    </collision>
    <visual>
      <origin rpy="0 0 0" xyz="-0.16 0 0.1725"/>
      <geometry>
        <box size="0.02 0.2 0.345"/>
      </geometry>
      <material name="white"/>
    </visual>
    <collision>
      <origin rpy="0 0 0" xyz="-0.16 0 0.1725"/>
      <geometry>
        <box size="0.02 0.2 0.345"/>
      </geometry>
    </collision>
    <visual>
      <origin rpy="0 0 0" xyz="0.145 0 0.1725"/>
      <geometry>
        <box size="0.05 0.2 0.345"/>
      </geometry>
      <material name="white"/>
    </visual>
    <collision>
      <origin rpy="0 0 0" xyz="0.145 0 0.1725"/>
      <geometry>
        <box size="0.05 0.2 0.345"/>
      </geometry>
    </collision>
    <inertial>
      <mass value="0.05"/>
      <inertia ixx="0.0001" iyy="0.0001" izz="0.0001"/>
    </inertial>
  </link>
  <joint name="1_motor2backlash" type="revolute">
    <limit lower="-0.1" upper="0.1"/>
    <dynamics damping="0.1" friction="0.1"/>
    <parent link="1_link1_bottom"/>
    <child link="1_motor2wheel"/>
    <axis xyz="0 0 1"/>
    <origin rpy="1.570796326795 0 1.570796326795" xyz="-0.15 0 0.24"/>
  </joint>
  <link name="1_motor2wheel">
    <visual>
      <origin rpy="0 0 0" xyz="0 0 0.01"/>
      <geometry>
        <cylinder length="0.02" radius="0.08"/>
      </geometry>
      <material name="red"/>
    </visual>
    <collision>
      <origin rpy="0 0 0" xyz="0 0 0.01"/>
      <geometry>
        <cylinder length="0.02" radius="0.08"/>
      </geometry>
    </collision>
    <inertial>
      <mass value="0.02"/>
      <inertia ixx="0.1" iyy="0.1" izz="0.1"/>
    </inertial>
  </link>
  <joint name="1_motor2joint" type="revolute">
    <parent link="1_motor2wheel"/>
    <child link="1_motor2link"/>
    <origin xyz="0 0 .02"/>
    <dynamics damping="0.1" friction="0.1"/>
    <limit lower="-1.570796326795" upper="1.570796326795"/>
    <axis xyz="0 0 1"/>
  </joint>
  <link name="1_motor2link">
    <visual>
      <origin xyz="0 .095 .125"/>
      <geometry>
        <box size=".24 .35 .25"/>
      </geometry>
      <material name="black"/>
    </visual>
    <collision>
      <origin xyz="0 .095 .125"/>
      <geometry>
        <box size=".24 .35 .25"/>
      </geometry>
    </collision>
    <inertial>
      <!--<mass value="${0.17 * weight}"/>-->
      <!--<inertia ixx="${.255 * inertia}" iyy="${.276 * inertia}" izz="${.185 * inertia}"/>-->
      <mass value="0.005"/>
      <inertia ixx="0.01" iyy="0.01" izz="0.01"/>
    </inertial>
  </link>
  <joint name="1_motor2link_to_motor2bridge3" type="fixed">
    <parent link="1_motor2link"/>
    <child link="1_motor2bridge3"/>
    <origin rpy="0 -1.570796326795 -1.570796326795" xyz="0 .19 .13"/>
  </joint>
  <link name="1_motor2bridge3">
    <visual>
      <origin rpy="0 0 0" xyz="-0.16 0 0.225"/>
      <geometry>
        <box size="0.02 0.2 0.45"/>
      </geometry>
      <material name="white"/>
    </visual>
    <collision>
      <origin rpy="0 0 0" xyz="-0.16 0 0.225"/>
      <geometry>
        <box size="0.02 0.2 0.45"/>
      </geometry>
    </collision>
    <visual>
      <origin rpy="0 0 0" xyz="0.145 0 0.225"/>
      <geometry>
        <box size="0.05 0.2 0.45"/>
      </geometry>
      <material name="white"/>
    </visual>
    <collision>
      <origin rpy="0 0 0" xyz="0.145 0 0.225"/>
      <geometry>
        <box size="0.05 0.2 0.45"/>
      </geometry>
    </collision>
    <inertial>
      <mass value="0.045"/>
      <inertia ixx="0.0001" iyy="0.0001" izz="0.0001"/>
    </inertial>
  </link>
  <joint name="1_motor3backlash" type="revolute">
    <limit lower="-0.1" upper="0.1"/>
    <dynamics damping="0.1" friction="0.1"/>
    <parent link="1_motor2bridge3"/>
    <child link="1_motor3wheel"/>
    <axis xyz="0 0 1"/>
    <origin rpy="1.570796326795 0 1.570796326795" xyz="-0.15 0 0.35"/>
  </joint>
  <link name="1_motor3wheel">
    <visual>
      <origin rpy="0 0 0" xyz="0 0 0.01"/>
      <geometry>
        <cylinder length="0.02" radius="0.08"/>
      </geometry>
      <material name="red"/>
    </visual>
    <collision>
      <origin rpy="0 0 0" xyz="0 0 0.01"/>
      <geometry>
        <cylinder length="0.02" radius="0.08"/>
      </geometry>
    </collision>
    <inertial>
      <mass value="0.02"/>
      <inertia ixx="0.1" iyy="0.1" izz="0.1"/>
    </inertial>
  </link>
  <joint name="1_motor3joint" type="revolute">
    <parent link="1_motor3wheel"/>
    <child link="1_motor3link"/>
    <origin xyz="0 0 .02"/>
    <dynamics damping="0.1" friction="0.1"/>
    <limit lower="-1.570796326795" upper="1.570796326795"/>
    <axis xyz="0 0 1"/>
  </joint>
  <link name="1_motor3link">
    <visual>
      <origin xyz="0 .095 .125"/>
      <geometry>
        <box size=".24 .35 .25"/>
      </geometry>
      <material name="black"/>
    </visual>
    <collision>
      <origin xyz="0 .095 .125"/>
      <geometry>
        <box size=".24 .35 .25"/>
      </geometry>
    </collision>
    <inertial>
      <!--<mass value="${0.17 * weight}"/>-->
      <!--<inertia ixx="${.255 * inertia}" iyy="${.276 * inertia}" izz="${.185 * inertia}"/>-->
      <mass value="0.005"/>
      <inertia ixx="0.01" iyy="0.01" izz="0.01"/>
    </inertial>
  </link>
  <joint name="1_motor3link_to_motor3bridge4" type="fixed">
    <parent link="1_motor3link"/>
    <child link="1_motor3bridge4"/>
    <origin rpy="0 -1.570796326795 -1.570796326795" xyz="0 .19 .13"/>
  </joint>
  <link name="1_motor3bridge4">
    <visual>
      <origin rpy="0 0 0" xyz="-0.015 0 0.09"/>
      <geometry>
        <box size="0.27 0.2 0.02"/>
      </geometry>
      <material name="white"/>
    </visual>
    <collision>
      <origin rpy="0 0 0" xyz="-0.015 0 0.09"/>
      <geometry>
        <box size="0.27 0.2 0.02"/>
      </geometry>
    </collision>
    <inertial>
      <mass value="0.01"/>
      <inertia ixx="0.0001" iyy="0.0001" izz="0.0001"/>
    </inertial>
  </link>
  <joint name="1_motor4backlash" type="revolute">
    <limit lower="-0.1" upper="0.1"/>
    <dynamics damping="0.1" friction="0.1"/>
    <parent link="1_motor3bridge4"/>
    <child link="1_motor4wheel"/>
    <axis xyz="0 0 1"/>
    <origin rpy="0 0 0" xyz="0 0 0.1"/>
  </joint>
  <link name="1_motor4wheel">
    <visual>
      <origin rpy="0 0 0" xyz="0 0 0.01"/>
      <geometry>
        <cylinder length="0.02" radius="0.08"/>
      </geometry>
      <material name="red"/>
    </visual>
    <collision>
      <origin rpy="0 0 0" xyz="0 0 0.01"/>
      <geometry>
        <cylinder length="0.02" radius="0.08"/>
      </geometry>
    </collision>
    <inertial>
      <mass value="0.02"/>
      <inertia ixx="0.1" iyy="0.1" izz="0.1"/>
    </inertial>
  </link>
  <joint name="1_motor4joint" type="revolute">
    <parent link="1_motor4wheel"/>
    <child link="1_motor4link"/>
    <origin xyz="0 0 .02"/>
    <dynamics damping="0.1" friction="0.1"/>
    <limit lower="-1.570796326795" upper="1.570796326795"/>
    <axis xyz="0 0 1"/>
  </joint>
  <link name="1_motor4link">
    <visual>
      <origin xyz="0 .095 .125"/>
      <geometry>
        <box size=".24 .35 .25"/>
      </geometry>
      <material name="black"/>
    </visual>
    <collision>
      <origin xyz="0 .095 .125"/>
      <geometry>
        <box size=".24 .35 .25"/>
      </geometry>
    </collision>
    <inertial>
      <!--<mass value="${0.17 * weight}"/>-->
      <!--<inertia ixx="${.255 * inertia}" iyy="${.276 * inertia}" izz="${.185 * inertia}"/>-->
      <mass value="0.005"/>
      <inertia ixx="0.01" iyy="0.01" izz="0.01"/>
    </inertial>
  </link>
  <joint name="1_motor4link_to_motor4bridge5" type="fixed">
    <parent link="1_motor4link"/>
    <child link="1_motor4bridge5"/>
    <origin rpy="3.14159265359 -3.14159265359 -3.14159265359" xyz="0 .19 .13"/>
  </joint>
  <link name="1_motor4bridge5">
    <visual>
      <origin rpy="0 0 0" xyz="-0.16 0.225 0"/>
      <geometry>
        <box size="0.02 0.45 0.2"/>
      </geometry>
      <material name="white"/>
    </visual>
    <collision>
      <origin rpy="0 0 0" xyz="-0.16 0.225 0"/>
      <geometry>
        <box size="0.02 0.45 0.2"/>
      </geometry>
    </collision>
    <visual>
      <origin rpy="0 0 0" xyz="-0.135 0.025 0"/>
      <geometry>
        <box size="0.03 0.05 0.2"/>
      </geometry>
      <material name="white"/>
    </visual>
    <collision>
      <origin rpy="0 0 0" xyz="-0.135 0.025 0"/>
      <geometry>
        <box size="0.03 0.05 0.2"/>
      </geometry>
    </collision>
    <visual>
      <origin rpy="0 0 0" xyz="0.14 0.225 0"/>
      <geometry>
        <box size="0.04 0.45 0.2"/>
      </geometry>
      <material name="white"/>
    </visual>
    <collision>
      <origin rpy="0 0 0" xyz="0.14 0.225 0"/>
      <geometry>
        <box size="0.04 0.45 0.2"/>
      </geometry>
    </collision>
    <inertial>
      <mass value="0.045"/>
      <inertia ixx="0.0001" iyy="0.0001" izz="0.0001"/>
    </inertial>
  </link>
  <joint name="1_motor5backlash" type="revolute">
    <limit lower="-0.1" upper="0.1"/>
    <dynamics damping="0.1" friction="0.1"/>
    <parent link="1_motor4bridge5"/>
    <child link="1_motor5wheel"/>
    <axis xyz="0 0 1"/>
    <origin rpy="0 1.570796326795 0" xyz="-0.15 0.35 0"/>
  </joint>
  <link name="1_motor5wheel">
    <visual>
      <origin rpy="0 0 0" xyz="0 0 0.01"/>
      <geometry>
        <cylinder length="0.02" radius="0.08"/>
      </geometry>
      <material name="red"/>
    </visual>
    <collision>
      <origin rpy="0 0 0" xyz="0 0 0.01"/>
      <geometry>
        <cylinder length="0.02" radius="0.08"/>
      </geometry>
    </collision>
    <inertial>
      <mass value="0.02"/>
      <inertia ixx="0.1" iyy="0.1" izz="0.1"/>
    </inertial>
  </link>
  <joint name="1_motor5joint" type="revolute">
    <parent link="1_motor5wheel"/>
    <child link="1_motor5link"/>
    <origin xyz="0 0 .02"/>
    <dynamics damping="0.1" friction="0.1"/>
    <limit lower="-1.570796326795" upper="1.570796326795"/>
    <axis xyz="0 0 1"/>
  </joint>
  <link name="1_motor5link">
    <visual>
      <origin xyz="0 .095 .125"/>
      <geometry>
        <box size=".24 .35 .25"/>
      </geometry>
      <material name="black"/>
    </visual>
    <collision>
      <origin xyz="0 .095 .125"/>
      <geometry>
        <box size=".24 .35 .25"/>
      </geometry>
    </collision>
    <inertial>
      <!--<mass value="${0.17 * weight}"/>-->
      <!--<inertia ixx="${.255 * inertia}" iyy="${.276 * inertia}" izz="${.185 * inertia}"/>-->
      <mass value="0.005"/>
      <inertia ixx="0.01" iyy="0.01" izz="0.01"/>
    </inertial>
  </link>
  <joint name="1_motor5link_to_motor5bridge6" type="fixed">
    <parent link="1_motor5link"/>
    <child link="1_motor5bridge6"/>
    <origin rpy="1.570796326795 -1.570796326795 -1.570796326795" xyz="0 .19 .13"/>
  </joint>
  <link name="1_motor5bridge6">
    <visual>
      <origin rpy="0 0 0" xyz="-0.16 0.225 0"/>
      <geometry>
        <box size="0.02 0.45 0.2"/>
      </geometry>
      <material name="white"/>
    </visual>
    <collision>
      <origin rpy="0 0 0" xyz="-0.16 0.225 0"/>
      <geometry>
        <box size="0.02 0.45 0.2"/>
      </geometry>
    </collision>
    <visual>
      <origin rpy="0 0 0" xyz="0.14 0.225 0"/>
      <geometry>
        <box size="0.04 0.45 0.2"/>
      </geometry>
      <material name="white"/>
    </visual>
    <collision>
      <origin rpy="0 0 0" xyz="0.14 0.225 0"/>
      <geometry>
        <box size="0.04 0.45 0.2"/>
      </geometry>
    </collision>
    <inertial>
      <mass value="0.045"/>
      <inertia ixx="0.0001" iyy="0.0001" izz="0.0001"/>
    </inertial>
  </link>
  <joint name="1_motor6backlash" type="revolute">
    <limit lower="-0.1" upper="0.1"/>
    <dynamics damping="0.1" friction="0.1"/>
    <parent link="1_motor5bridge6"/>
    <child link="1_motor6wheel"/>
    <axis xyz="0 0 1"/>
    <origin rpy="0 1.570796326795 0" xyz="-0.15 0.35 0"/>
  </joint>
  <link name="1_motor6wheel">
    <visual>
      <origin rpy="0 0 0" xyz="0 0 0.01"/>
      <geometry>
        <cylinder length="0.02" radius="0.08"/>
      </geometry>
      <material name="red"/>
    </visual>
    <collision>
      <origin rpy="0 0 0" xyz="0 0 0.01"/>
      <geometry>
        <cylinder length="0.02" radius="0.08"/>
      </geometry>
    </collision>
    <inertial>
      <mass value="0.02"/>
      <inertia ixx="0.1" iyy="0.1" izz="0.1"/>
    </inertial>
  </link>
  <joint name="1_motor6joint" type="revolute">
    <parent link="1_motor6wheel"/>
    <child link="1_motor6link"/>
    <origin xyz="0 0 .02"/>
    <dynamics damping="0.1" friction="0.1"/>
    <limit lower="-1.570796326795" upper="1.570796326795"/>
    <axis xyz="0 0 1"/>
  </joint>
  <link name="1_motor6link">
    <visual>
      <origin xyz="0 .095 .125"/>
      <geometry>
        <box size=".24 .35 .25"/>
      </geometry>
      <material name="black"/>
    </visual>
    <collision>
      <origin xyz="0 .095 .125"/>
      <geometry>
        <box size=".24 .35 .25"/>
      </geometry>
    </collision>
    <inertial>
      <!--<mass value="${0.17 * weight}"/>-->
      <!--<inertia ixx="${.255 * inertia}" iyy="${.276 * inertia}" izz="${.185 * inertia}"/>-->
      <mass value="0.005"/>
      <inertia ixx="0.01" iyy="0.01" izz="0.01"/>
    </inertial>
  </link>
  <joint name="motor6link_to_penholder" type="fixed">
    <parent link="1_motor6link"/>
    <child link="penholder"/>
    <origin rpy="0 1.570796326795 0" xyz="0 .30 .125"/>
  </joint>
  <link name="penholder">
    <visual>
      <origin rpy="0 0 0" xyz="0 -0.01 0"/>
      <geometry>
        <box size="0.24 0.04 0.2"/>
      </geometry>
      <material name="white"/>
    </visual>
    <collision>
      <origin rpy="0 0 0" xyz="0 -0.01 0"/>
      <geometry>
        <box size="0.24 0.04 0.2"/>
      </geometry>
    </collision>
    <visual>
      <origin rpy="0 0 0" xyz="0 0.07 0"/>
      <geometry>
        <cylinder length="0.2" radius="0.07"/>
      </geometry>
      <material name="white"/>
    </visual>
    <collision>
      <origin rpy="0 0 0" xyz="0 0.07 0"/>
      <geometry>
        <cylinder length="0.2" radius="0.07"/>
      </geometry>
    </collision>
    <inertial>
      <mass value="0.04"/>
      <inertia ixx="0.0001" iyy="0.0001" izz="0.0001"/>
    </inertial>
  </link>
</robot>
